{"uuid": "5fc2010d-6190-42ff-a663-a7722ae005a2", "counter": 8, "stdout": "\u001b[0;31mAn exception occurred during task execution. To see the full traceback, use -vvv. The error was: ovirtsdk4.Error: The CA file '/home/morozovms/NPIS/backend/pki-resource.crt' doesn't exist\u001b[0m\r\n\u001b[0;31mfatal: [localhost]: FAILED! => {\"changed\": false, \"module_stderr\": \"Traceback (most recent call last):\\n  File \\\"/root/.ansible/tmp/ansible-tmp-1734773059.6977851-16872-220140790046833/AnsiballZ_ovirt_auth.py\\\", line 107, in <module>\\n    _ansiballz_main()\\n  File \\\"/root/.ansible/tmp/ansible-tmp-1734773059.6977851-16872-220140790046833/AnsiballZ_ovirt_auth.py\\\", line 99, in _ansiballz_main\\n    invoke_module(zipped_mod, temp_path, ANSIBALLZ_PARAMS)\\n  File \\\"/root/.ansible/tmp/ansible-tmp-1734773059.6977851-16872-220140790046833/AnsiballZ_ovirt_auth.py\\\", line 47, in invoke_module\\n    runpy.run_module(mod_name='ansible_collections.ovirt.ovirt.plugins.modules.ovirt_auth', init_globals=dict(_module_fqn='ansible_collections.ovirt.ovirt.plugins.modules.ovirt_auth', _modlib_path=modlib_path),\\n  File \\\"<frozen runpy>\\\", line 226, in run_module\\n  File \\\"<frozen runpy>\\\", line 98, in _run_module_code\\n  File \\\"<frozen runpy>\\\", line 88, in _run_code\\n  File \\\"/tmp/ansible_ovirt.ovirt.ovirt_auth_payload_8wvfwe0t/ansible_ovirt.ovirt.ovirt_auth_payload.zip/ansible_collections/ovirt/ovirt/plugins/modules/ovirt_auth.py\\\", line 311, in <module>\\n  File \\\"/tmp/ansible_ovirt.ovirt.ovirt_auth_payload_8wvfwe0t/ansible_ovirt.ovirt.ovirt_auth_payload.zip/ansible_collections/ovirt/ovirt/plugins/modules/ovirt_auth.py\\\", line 274, in main\\n  File \\\"/NPIS/venv/lib/python3.12/site-packages/ovirtsdk4/__init__.py\\\", line 308, in __init__\\n    raise Error('The CA file \\\\'%s\\\\' doesn\\\\'t exist' % ca_file)\\novirtsdk4.Error: The CA file '/home/morozovms/NPIS/backend/pki-resource.crt' doesn't exist\\n\", \"module_stdout\": \"\", \"msg\": \"MODULE FAILURE: No start of json char found\\nSee stdout/stderr for the exact error\", \"rc\": 1}\u001b[0m", "start_line": 7, "end_line": 9, "runner_ident": "533b5e17-1ff9-48b1-bd45-4a5edd325eca", "event": "runner_on_failed", "pid": 16868, "created": "2024-12-21T09:24:20.114129+00:00", "parent_uuid": "000c298e-0dd6-1c11-a1c6-000000000003", "event_data": {"playbook": "ansible/test.yml", "playbook_uuid": "e4c65234-90fb-4cab-b64e-02508450f7ff", "play": "\u0421\u0431\u043e\u0440 \u0438\u043d\u0444\u043e\u0440\u043c\u0430\u0446\u0438\u0438 \u043e \u0441\u043e\u0437\u0434\u0430\u043d\u043d\u044b\u0445 \u0432\u0438\u0440\u0442\u0443\u0430\u043b\u044c\u043d\u044b\u0445 \u043c\u0430\u0448\u0438\u043d\u0430\u0445 \u0432 oVirt", "play_uuid": "000c298e-0dd6-1c11-a1c6-000000000001", "play_pattern": "localhost", "task": "\u0410\u0443\u0442\u0435\u043d\u0442\u0438\u0444\u0438\u043a\u0430\u0446\u0438\u044f \u0432 oVirt", "task_uuid": "000c298e-0dd6-1c11-a1c6-000000000003", "task_action": "ovirt.ovirt.ovirt_auth", "resolved_action": "ovirt.ovirt.ovirt_auth", "task_args": "", "task_path": "/NPIS/backend/ansible/test.yml:11", "host": "localhost", "remote_addr": "127.0.0.1", "res": {"module_stdout": "", "module_stderr": "Traceback (most recent call last):\n  File \"/root/.ansible/tmp/ansible-tmp-1734773059.6977851-16872-220140790046833/AnsiballZ_ovirt_auth.py\", line 107, in <module>\n    _ansiballz_main()\n  File \"/root/.ansible/tmp/ansible-tmp-1734773059.6977851-16872-220140790046833/AnsiballZ_ovirt_auth.py\", line 99, in _ansiballz_main\n    invoke_module(zipped_mod, temp_path, ANSIBALLZ_PARAMS)\n  File \"/root/.ansible/tmp/ansible-tmp-1734773059.6977851-16872-220140790046833/AnsiballZ_ovirt_auth.py\", line 47, in invoke_module\n    runpy.run_module(mod_name='ansible_collections.ovirt.ovirt.plugins.modules.ovirt_auth', init_globals=dict(_module_fqn='ansible_collections.ovirt.ovirt.plugins.modules.ovirt_auth', _modlib_path=modlib_path),\n  File \"<frozen runpy>\", line 226, in run_module\n  File \"<frozen runpy>\", line 98, in _run_module_code\n  File \"<frozen runpy>\", line 88, in _run_code\n  File \"/tmp/ansible_ovirt.ovirt.ovirt_auth_payload_8wvfwe0t/ansible_ovirt.ovirt.ovirt_auth_payload.zip/ansible_collections/ovirt/ovirt/plugins/modules/ovirt_auth.py\", line 311, in <module>\n  File \"/tmp/ansible_ovirt.ovirt.ovirt_auth_payload_8wvfwe0t/ansible_ovirt.ovirt.ovirt_auth_payload.zip/ansible_collections/ovirt/ovirt/plugins/modules/ovirt_auth.py\", line 274, in main\n  File \"/NPIS/venv/lib/python3.12/site-packages/ovirtsdk4/__init__.py\", line 308, in __init__\n    raise Error('The CA file \\'%s\\' doesn\\'t exist' % ca_file)\novirtsdk4.Error: The CA file '/home/morozovms/NPIS/backend/pki-resource.crt' doesn't exist\n", "exception": "Traceback (most recent call last):\n  File \"/root/.ansible/tmp/ansible-tmp-1734773059.6977851-16872-220140790046833/AnsiballZ_ovirt_auth.py\", line 107, in <module>\n    _ansiballz_main()\n  File \"/root/.ansible/tmp/ansible-tmp-1734773059.6977851-16872-220140790046833/AnsiballZ_ovirt_auth.py\", line 99, in _ansiballz_main\n    invoke_module(zipped_mod, temp_path, ANSIBALLZ_PARAMS)\n  File \"/root/.ansible/tmp/ansible-tmp-1734773059.6977851-16872-220140790046833/AnsiballZ_ovirt_auth.py\", line 47, in invoke_module\n    runpy.run_module(mod_name='ansible_collections.ovirt.ovirt.plugins.modules.ovirt_auth', init_globals=dict(_module_fqn='ansible_collections.ovirt.ovirt.plugins.modules.ovirt_auth', _modlib_path=modlib_path),\n  File \"<frozen runpy>\", line 226, in run_module\n  File \"<frozen runpy>\", line 98, in _run_module_code\n  File \"<frozen runpy>\", line 88, in _run_code\n  File \"/tmp/ansible_ovirt.ovirt.ovirt_auth_payload_8wvfwe0t/ansible_ovirt.ovirt.ovirt_auth_payload.zip/ansible_collections/ovirt/ovirt/plugins/modules/ovirt_auth.py\", line 311, in <module>\n  File \"/tmp/ansible_ovirt.ovirt.ovirt_auth_payload_8wvfwe0t/ansible_ovirt.ovirt.ovirt_auth_payload.zip/ansible_collections/ovirt/ovirt/plugins/modules/ovirt_auth.py\", line 274, in main\n  File \"/NPIS/venv/lib/python3.12/site-packages/ovirtsdk4/__init__.py\", line 308, in __init__\n    raise Error('The CA file \\'%s\\' doesn\\'t exist' % ca_file)\novirtsdk4.Error: The CA file '/home/morozovms/NPIS/backend/pki-resource.crt' doesn't exist\n", "msg": "MODULE FAILURE: No start of json char found\nSee stdout/stderr for the exact error", "rc": 1, "_ansible_no_log": false, "changed": false}, "start": "2024-12-21T09:24:19.677453+00:00", "end": "2024-12-21T09:24:20.113900+00:00", "duration": 0.436447, "ignore_errors": null, "event_loop": null, "uuid": "5fc2010d-6190-42ff-a663-a7722ae005a2"}}